New exception occured:

<%= @exception.message %>

<%= @exception.backtrace.join("\n") %>

